2022-02-13 14:12:00,583 - kedro.pipeline.node - ERROR - Node `split_target_node_dev: split_target([alldata,parameters]) -> [X_dev,y_dev]` failed with error: 
'DataFrame' object has no attribute 'str'
2022-02-13 14:20:44,198 - kedro.pipeline.node - ERROR - Node `split_train_test_node_dev: train_test_split([X_dev,parameters,y_dev]) -> [X_test,X_train,y_test,y_train]` failed with error: 
train_test_split() got an unexpected keyword argument 'test_size'
2022-02-13 14:21:26,342 - kedro.pipeline.node - ERROR - Node `split_train_test_node_dev: train_test_split([X_dev,parameters,y_dev]) -> [X_test,X_train,y_test,y_train]` failed with error: 
train_test_split() got an unexpected keyword argument 'test_size'
2022-02-13 14:22:24,454 - kedro.pipeline.node - ERROR - Node `split_train_test_node_dev: train_test_split([X_dev,parameters,y_dev]) -> [X_test,X_train,y_test,y_train]` failed with error: 
not enough values to unpack (expected 4, got 2)
2022-02-13 15:31:03,909 - kedro.pipeline.node - ERROR - Node `drop_irrelevant_covariates: drop_covariates([parameters,train]) -> [train_dropped]` failed with error: 
Failed to save outputs of node drop_irrelevant_covariates: drop_covariates([parameters,train]) -> [train_dropped].
The node definition contains a list of outputs ['train_dropped'], whereas the node function returned a `DataFrame`.
2022-02-13 15:33:11,527 - kedro.pipeline.node - ERROR - Node `fteng_categorical: process_categorical([parameters,train]) -> [train_categorical]` failed with error: 
"None of [Index(['MS.SubClass', 'MS.Zoning', 'Street', 'Alley', 'Land.Contour',\n       'Lot.Config', 'Neighborhood', 'Condition.1', 'Condition.2', 'Bldg.Type',\n       'House.Style', 'Roof.Style', 'Roof.Matl', 'Exterior.1st',\n       'Exterior.2nd', 'Mas.Vnr.Type', 'Foundation', 'Heating', 'Central.Air',\n       'Garage.Type', 'Sale.Type', 'Sale.Condition'],\n      dtype='object')] are in the [columns]"
2022-02-13 15:41:58,931 - uvicorn.error - ERROR - Exception in ASGI application
Traceback (most recent call last):
  File "/home/vpb/anaconda3/envs/kclonea/lib/python3.7/site-packages/uvicorn/protocols/http/httptools_impl.py", line 398, in run_asgi
    result = await app(self.scope, self.receive, self.send)
  File "/home/vpb/anaconda3/envs/kclonea/lib/python3.7/site-packages/uvicorn/middleware/proxy_headers.py", line 45, in __call__
    return await self.app(scope, receive, send)
  File "/home/vpb/anaconda3/envs/kclonea/lib/python3.7/site-packages/fastapi/applications.py", line 199, in __call__
    await super().__call__(scope, receive, send)
  File "/home/vpb/anaconda3/envs/kclonea/lib/python3.7/site-packages/starlette/applications.py", line 112, in __call__
    await self.middleware_stack(scope, receive, send)
  File "/home/vpb/anaconda3/envs/kclonea/lib/python3.7/site-packages/starlette/middleware/errors.py", line 181, in __call__
    raise exc from None
  File "/home/vpb/anaconda3/envs/kclonea/lib/python3.7/site-packages/starlette/middleware/errors.py", line 159, in __call__
    await self.app(scope, receive, _send)
  File "/home/vpb/anaconda3/envs/kclonea/lib/python3.7/site-packages/starlette/exceptions.py", line 82, in __call__
    raise exc from None
  File "/home/vpb/anaconda3/envs/kclonea/lib/python3.7/site-packages/starlette/exceptions.py", line 71, in __call__
    await self.app(scope, receive, sender)
  File "/home/vpb/anaconda3/envs/kclonea/lib/python3.7/site-packages/starlette/routing.py", line 580, in __call__
    await route.handle(scope, receive, send)
  File "/home/vpb/anaconda3/envs/kclonea/lib/python3.7/site-packages/starlette/routing.py", line 241, in handle
    await self.app(scope, receive, send)
  File "/home/vpb/anaconda3/envs/kclonea/lib/python3.7/site-packages/starlette/routing.py", line 52, in app
    response = await func(request)
  File "/home/vpb/anaconda3/envs/kclonea/lib/python3.7/site-packages/fastapi/routing.py", line 217, in app
    dependant=dependant, values=values, is_coroutine=is_coroutine
  File "/home/vpb/anaconda3/envs/kclonea/lib/python3.7/site-packages/fastapi/routing.py", line 149, in run_endpoint_function
    return await dependant.call(**values)
  File "/home/vpb/anaconda3/envs/kclonea/lib/python3.7/site-packages/kedro_viz/api/router.py", line 49, in get_single_node_metadata
    return TaskNodeMetadata(node)
  File "<string>", line 3, in __init__
  File "/home/vpb/anaconda3/envs/kclonea/lib/python3.7/site-packages/kedro_viz/models/graph.py", line 411, in __post_init__
    if inspect.isfunction(kedro_node.func):
AttributeError: 'Node' object has no attribute 'func'
2022-02-13 16:06:28,635 - kedro.pipeline.node - ERROR - Node `Join Categorical and Numerical - Test: join_num_cat([test_categorical,test_numeric]) -> [test_joined_num_cat]` failed with error: 
Failed to save outputs of node Join Categorical and Numerical - Test: join_num_cat([test_categorical,test_numeric]) -> [test_joined_num_cat].
The node definition contains a list of outputs ['test_joined_num_cat'], whereas the node function returned a `DataFrame`.
